Internal Server Error: /login/
Traceback (most recent call last):
  File "/Users/arnavshah/Documents/mafiawebsite/.venv/lib/python3.12/site-packages/django/template/defaulttags.py", line 1035, in find_library
    return parser.libraries[name]
           ~~~~~~~~~~~~~~~~^^^^^^
KeyError: 'recaptcha_tags'

During handling of the above exception, another exception occurred:

Traceback (most recent call last):
  File "/Users/arnavshah/Documents/mafiawebsite/.venv/lib/python3.12/site-packages/django/core/handlers/exception.py", line 55, in inner
    response = get_response(request)
               ^^^^^^^^^^^^^^^^^^^^^
  File "/Users/arnavshah/Documents/mafiawebsite/.venv/lib/python3.12/site-packages/django/core/handlers/base.py", line 220, in _get_response
    response = response.render()
               ^^^^^^^^^^^^^^^^^
  File "/Users/arnavshah/Documents/mafiawebsite/.venv/lib/python3.12/site-packages/django/template/response.py", line 114, in render
    self.content = self.rendered_content
                   ^^^^^^^^^^^^^^^^^^^^^
  File "/Users/arnavshah/Documents/mafiawebsite/.venv/lib/python3.12/site-packages/django/template/response.py", line 90, in rendered_content
    template = self.resolve_template(self.template_name)
               ^^^^^^^^^^^^^^^^^^^^^^^^^^^^^^^^^^^^^^^^^
  File "/Users/arnavshah/Documents/mafiawebsite/.venv/lib/python3.12/site-packages/django/template/response.py", line 72, in resolve_template
    return select_template(template, using=self.using)
           ^^^^^^^^^^^^^^^^^^^^^^^^^^^^^^^^^^^^^^^^^^^
  File "/Users/arnavshah/Documents/mafiawebsite/.venv/lib/python3.12/site-packages/django/template/loader.py", line 42, in select_template
    return engine.get_template(template_name)
           ^^^^^^^^^^^^^^^^^^^^^^^^^^^^^^^^^^
  File "/Users/arnavshah/Documents/mafiawebsite/.venv/lib/python3.12/site-packages/django/template/backends/django.py", line 79, in get_template
    return Template(self.engine.get_template(template_name), self)
                    ^^^^^^^^^^^^^^^^^^^^^^^^^^^^^^^^^^^^^^^
  File "/Users/arnavshah/Documents/mafiawebsite/.venv/lib/python3.12/site-packages/django/template/engine.py", line 177, in get_template
    template, origin = self.find_template(template_name)
                       ^^^^^^^^^^^^^^^^^^^^^^^^^^^^^^^^^
  File "/Users/arnavshah/Documents/mafiawebsite/.venv/lib/python3.12/site-packages/django/template/engine.py", line 159, in find_template
    template = loader.get_template(name, skip=skip)
               ^^^^^^^^^^^^^^^^^^^^^^^^^^^^^^^^^^^^
  File "/Users/arnavshah/Documents/mafiawebsite/.venv/lib/python3.12/site-packages/django/template/loaders/cached.py", line 57, in get_template
    template = super().get_template(template_name, skip)
               ^^^^^^^^^^^^^^^^^^^^^^^^^^^^^^^^^^^^^^^^^
  File "/Users/arnavshah/Documents/mafiawebsite/.venv/lib/python3.12/site-packages/django/template/loaders/base.py", line 28, in get_template
    return Template(
           ^^^^^^^^^
  File "/Users/arnavshah/Documents/mafiawebsite/.venv/lib/python3.12/site-packages/django/template/base.py", line 154, in __init__
    self.nodelist = self.compile_nodelist()
                    ^^^^^^^^^^^^^^^^^^^^^^^
  File "/Users/arnavshah/Documents/mafiawebsite/.venv/lib/python3.12/site-packages/django/template/base.py", line 196, in compile_nodelist
    nodelist = parser.parse()
               ^^^^^^^^^^^^^^
  File "/Users/arnavshah/Documents/mafiawebsite/.venv/lib/python3.12/site-packages/django/template/base.py", line 518, in parse
    raise self.error(token, e)
  File "/Users/arnavshah/Documents/mafiawebsite/.venv/lib/python3.12/site-packages/django/template/base.py", line 516, in parse
    compiled_result = compile_func(self, token)
                      ^^^^^^^^^^^^^^^^^^^^^^^^^
  File "/Users/arnavshah/Documents/mafiawebsite/.venv/lib/python3.12/site-packages/django/template/loader_tags.py", line 295, in do_extends
    nodelist = parser.parse()
               ^^^^^^^^^^^^^^
  File "/Users/arnavshah/Documents/mafiawebsite/.venv/lib/python3.12/site-packages/django/template/base.py", line 518, in parse
    raise self.error(token, e)
  File "/Users/arnavshah/Documents/mafiawebsite/.venv/lib/python3.12/site-packages/django/template/base.py", line 516, in parse
    compiled_result = compile_func(self, token)
                      ^^^^^^^^^^^^^^^^^^^^^^^^^
  File "/Users/arnavshah/Documents/mafiawebsite/.venv/lib/python3.12/site-packages/django/template/defaulttags.py", line 1097, in load
    lib = find_library(parser, name)
          ^^^^^^^^^^^^^^^^^^^^^^^^^^
  File "/Users/arnavshah/Documents/mafiawebsite/.venv/lib/python3.12/site-packages/django/template/defaulttags.py", line 1037, in find_library
    raise TemplateSyntaxError(
django.template.exceptions.TemplateSyntaxError: 'recaptcha_tags' is not a registered tag library. Must be one of:
admin_list
admin_modify
admin_urls
cache
i18n
l10n
log
static
tz
widget_tweaks
"GET /login/ HTTP/1.1" 500 184100
Internal Server Error: /register/
Traceback (most recent call last):
  File "/Users/arnavshah/Documents/mafiawebsite/.venv/lib/python3.12/site-packages/django/core/handlers/exception.py", line 55, in inner
    response = get_response(request)
               ^^^^^^^^^^^^^^^^^^^^^
  File "/Users/arnavshah/Documents/mafiawebsite/.venv/lib/python3.12/site-packages/django/core/handlers/base.py", line 197, in _get_response
    response = wrapped_callback(request, *callback_args, **callback_kwargs)
               ^^^^^^^^^^^^^^^^^^^^^^^^^^^^^^^^^^^^^^^^^^^^^^^^^^^^^^^^^^^^
  File "/Users/arnavshah/Documents/mafiawebsite/myapp/views.py", line 610, in register
    'form': form,
            ^^^^
NameError: name 'form' is not defined
"GET /register/ HTTP/1.1" 500 64927
Internal Server Error: /login/
Traceback (most recent call last):
  File "/Users/arnavshah/Documents/mafiawebsite/.venv/lib/python3.12/site-packages/django/template/defaulttags.py", line 1035, in find_library
    return parser.libraries[name]
           ~~~~~~~~~~~~~~~~^^^^^^
KeyError: 'recaptcha_tags'

During handling of the above exception, another exception occurred:

Traceback (most recent call last):
  File "/Users/arnavshah/Documents/mafiawebsite/.venv/lib/python3.12/site-packages/django/core/handlers/exception.py", line 55, in inner
    response = get_response(request)
               ^^^^^^^^^^^^^^^^^^^^^
  File "/Users/arnavshah/Documents/mafiawebsite/.venv/lib/python3.12/site-packages/django/core/handlers/base.py", line 220, in _get_response
    response = response.render()
               ^^^^^^^^^^^^^^^^^
  File "/Users/arnavshah/Documents/mafiawebsite/.venv/lib/python3.12/site-packages/django/template/response.py", line 114, in render
    self.content = self.rendered_content
                   ^^^^^^^^^^^^^^^^^^^^^
  File "/Users/arnavshah/Documents/mafiawebsite/.venv/lib/python3.12/site-packages/django/template/response.py", line 90, in rendered_content
    template = self.resolve_template(self.template_name)
               ^^^^^^^^^^^^^^^^^^^^^^^^^^^^^^^^^^^^^^^^^
  File "/Users/arnavshah/Documents/mafiawebsite/.venv/lib/python3.12/site-packages/django/template/response.py", line 72, in resolve_template
    return select_template(template, using=self.using)
           ^^^^^^^^^^^^^^^^^^^^^^^^^^^^^^^^^^^^^^^^^^^
  File "/Users/arnavshah/Documents/mafiawebsite/.venv/lib/python3.12/site-packages/django/template/loader.py", line 42, in select_template
    return engine.get_template(template_name)
           ^^^^^^^^^^^^^^^^^^^^^^^^^^^^^^^^^^
  File "/Users/arnavshah/Documents/mafiawebsite/.venv/lib/python3.12/site-packages/django/template/backends/django.py", line 79, in get_template
    return Template(self.engine.get_template(template_name), self)
                    ^^^^^^^^^^^^^^^^^^^^^^^^^^^^^^^^^^^^^^^
  File "/Users/arnavshah/Documents/mafiawebsite/.venv/lib/python3.12/site-packages/django/template/engine.py", line 177, in get_template
    template, origin = self.find_template(template_name)
                       ^^^^^^^^^^^^^^^^^^^^^^^^^^^^^^^^^
  File "/Users/arnavshah/Documents/mafiawebsite/.venv/lib/python3.12/site-packages/django/template/engine.py", line 159, in find_template
    template = loader.get_template(name, skip=skip)
               ^^^^^^^^^^^^^^^^^^^^^^^^^^^^^^^^^^^^
  File "/Users/arnavshah/Documents/mafiawebsite/.venv/lib/python3.12/site-packages/django/template/loaders/cached.py", line 57, in get_template
    template = super().get_template(template_name, skip)
               ^^^^^^^^^^^^^^^^^^^^^^^^^^^^^^^^^^^^^^^^^
  File "/Users/arnavshah/Documents/mafiawebsite/.venv/lib/python3.12/site-packages/django/template/loaders/base.py", line 28, in get_template
    return Template(
           ^^^^^^^^^
  File "/Users/arnavshah/Documents/mafiawebsite/.venv/lib/python3.12/site-packages/django/template/base.py", line 154, in __init__
    self.nodelist = self.compile_nodelist()
                    ^^^^^^^^^^^^^^^^^^^^^^^
  File "/Users/arnavshah/Documents/mafiawebsite/.venv/lib/python3.12/site-packages/django/template/base.py", line 196, in compile_nodelist
    nodelist = parser.parse()
               ^^^^^^^^^^^^^^
  File "/Users/arnavshah/Documents/mafiawebsite/.venv/lib/python3.12/site-packages/django/template/base.py", line 518, in parse
    raise self.error(token, e)
  File "/Users/arnavshah/Documents/mafiawebsite/.venv/lib/python3.12/site-packages/django/template/base.py", line 516, in parse
    compiled_result = compile_func(self, token)
                      ^^^^^^^^^^^^^^^^^^^^^^^^^
  File "/Users/arnavshah/Documents/mafiawebsite/.venv/lib/python3.12/site-packages/django/template/loader_tags.py", line 295, in do_extends
    nodelist = parser.parse()
               ^^^^^^^^^^^^^^
  File "/Users/arnavshah/Documents/mafiawebsite/.venv/lib/python3.12/site-packages/django/template/base.py", line 518, in parse
    raise self.error(token, e)
  File "/Users/arnavshah/Documents/mafiawebsite/.venv/lib/python3.12/site-packages/django/template/base.py", line 516, in parse
    compiled_result = compile_func(self, token)
                      ^^^^^^^^^^^^^^^^^^^^^^^^^
  File "/Users/arnavshah/Documents/mafiawebsite/.venv/lib/python3.12/site-packages/django/template/defaulttags.py", line 1097, in load
    lib = find_library(parser, name)
          ^^^^^^^^^^^^^^^^^^^^^^^^^^
  File "/Users/arnavshah/Documents/mafiawebsite/.venv/lib/python3.12/site-packages/django/template/defaulttags.py", line 1037, in find_library
    raise TemplateSyntaxError(
django.template.exceptions.TemplateSyntaxError: 'recaptcha_tags' is not a registered tag library. Must be one of:
admin_list
admin_modify
admin_urls
cache
i18n
l10n
log
static
tz
widget_tweaks
"GET /login/ HTTP/1.1" 500 184100
You're accessing the development server over HTTPS, but it only supports HTTP.
You're accessing the development server over HTTPS, but it only supports HTTP.
You're accessing the development server over HTTPS, but it only supports HTTP.
You're accessing the development server over HTTPS, but it only supports HTTP.
You're accessing the development server over HTTPS, but it only supports HTTP.
You're accessing the development server over HTTPS, but it only supports HTTP.
You're accessing the development server over HTTPS, but it only supports HTTP.
You're accessing the development server over HTTPS, but it only supports HTTP.
You're accessing the development server over HTTPS, but it only supports HTTP.
You're accessing the development server over HTTPS, but it only supports HTTP.
You're accessing the development server over HTTPS, but it only supports HTTP.
You're accessing the development server over HTTPS, but it only supports HTTP.
You're accessing the development server over HTTPS, but it only supports HTTP.
You're accessing the development server over HTTPS, but it only supports HTTP.
You're accessing the development server over HTTPS, but it only supports HTTP.
You're accessing the development server over HTTPS, but it only supports HTTP.
You're accessing the development server over HTTPS, but it only supports HTTP.
You're accessing the development server over HTTPS, but it only supports HTTP.
You're accessing the development server over HTTPS, but it only supports HTTP.
You're accessing the development server over HTTPS, but it only supports HTTP.
You're accessing the development server over HTTPS, but it only supports HTTP.
You're accessing the development server over HTTPS, but it only supports HTTP.
You're accessing the development server over HTTPS, but it only supports HTTP.
You're accessing the development server over HTTPS, but it only supports HTTP.
You're accessing the development server over HTTPS, but it only supports HTTP.
You're accessing the development server over HTTPS, but it only supports HTTP.
Internal Server Error: /register/
Traceback (most recent call last):
  File "/Users/arnavshah/Documents/mafiawebsite/.venv/lib/python3.12/site-packages/django/db/backends/utils.py", line 105, in _execute
    return self.cursor.execute(sql, params)
           ^^^^^^^^^^^^^^^^^^^^^^^^^^^^^^^^
psycopg2.errors.UndefinedTable: relation "myapp_emailverification" does not exist
LINE 1: INSERT INTO "myapp_emailverification" ("user_id", "code", "c...
                    ^


The above exception was the direct cause of the following exception:

Traceback (most recent call last):
  File "/Users/arnavshah/Documents/mafiawebsite/.venv/lib/python3.12/site-packages/django/core/handlers/exception.py", line 55, in inner
    response = get_response(request)
               ^^^^^^^^^^^^^^^^^^^^^
  File "/Users/arnavshah/Documents/mafiawebsite/.venv/lib/python3.12/site-packages/django/core/handlers/base.py", line 197, in _get_response
    response = wrapped_callback(request, *callback_args, **callback_kwargs)
               ^^^^^^^^^^^^^^^^^^^^^^^^^^^^^^^^^^^^^^^^^^^^^^^^^^^^^^^^^^^^
  File "/Users/arnavshah/Documents/mafiawebsite/myapp/views.py", line 410, in register
    EmailVerification.objects.create(user=user, code=code)
  File "/Users/arnavshah/Documents/mafiawebsite/.venv/lib/python3.12/site-packages/django/db/models/manager.py", line 87, in manager_method
    return getattr(self.get_queryset(), name)(*args, **kwargs)
           ^^^^^^^^^^^^^^^^^^^^^^^^^^^^^^^^^^^^^^^^^^^^^^^^^^^
  File "/Users/arnavshah/Documents/mafiawebsite/.venv/lib/python3.12/site-packages/django/db/models/query.py", line 679, in create
    obj.save(force_insert=True, using=self.db)
  File "/Users/arnavshah/Documents/mafiawebsite/.venv/lib/python3.12/site-packages/django/db/models/base.py", line 891, in save
    self.save_base(
  File "/Users/arnavshah/Documents/mafiawebsite/.venv/lib/python3.12/site-packages/django/db/models/base.py", line 997, in save_base
    updated = self._save_table(
              ^^^^^^^^^^^^^^^^^
  File "/Users/arnavshah/Documents/mafiawebsite/.venv/lib/python3.12/site-packages/django/db/models/base.py", line 1160, in _save_table
    results = self._do_insert(
              ^^^^^^^^^^^^^^^^
  File "/Users/arnavshah/Documents/mafiawebsite/.venv/lib/python3.12/site-packages/django/db/models/base.py", line 1201, in _do_insert
    return manager._insert(
           ^^^^^^^^^^^^^^^^
  File "/Users/arnavshah/Documents/mafiawebsite/.venv/lib/python3.12/site-packages/django/db/models/manager.py", line 87, in manager_method
    return getattr(self.get_queryset(), name)(*args, **kwargs)
           ^^^^^^^^^^^^^^^^^^^^^^^^^^^^^^^^^^^^^^^^^^^^^^^^^^^
  File "/Users/arnavshah/Documents/mafiawebsite/.venv/lib/python3.12/site-packages/django/db/models/query.py", line 1847, in _insert
    return query.get_compiler(using=using).execute_sql(returning_fields)
           ^^^^^^^^^^^^^^^^^^^^^^^^^^^^^^^^^^^^^^^^^^^^^^^^^^^^^^^^^^^^^
  File "/Users/arnavshah/Documents/mafiawebsite/.venv/lib/python3.12/site-packages/django/db/models/sql/compiler.py", line 1836, in execute_sql
    cursor.execute(sql, params)
  File "/Users/arnavshah/Documents/mafiawebsite/.venv/lib/python3.12/site-packages/django/db/backends/utils.py", line 122, in execute
    return super().execute(sql, params)
           ^^^^^^^^^^^^^^^^^^^^^^^^^^^^
  File "/Users/arnavshah/Documents/mafiawebsite/.venv/lib/python3.12/site-packages/django/db/backends/utils.py", line 79, in execute
    return self._execute_with_wrappers(
           ^^^^^^^^^^^^^^^^^^^^^^^^^^^^
  File "/Users/arnavshah/Documents/mafiawebsite/.venv/lib/python3.12/site-packages/django/db/backends/utils.py", line 92, in _execute_with_wrappers
    return executor(sql, params, many, context)
           ^^^^^^^^^^^^^^^^^^^^^^^^^^^^^^^^^^^^
  File "/Users/arnavshah/Documents/mafiawebsite/.venv/lib/python3.12/site-packages/django/db/backends/utils.py", line 100, in _execute
    with self.db.wrap_database_errors:
  File "/Users/arnavshah/Documents/mafiawebsite/.venv/lib/python3.12/site-packages/django/db/utils.py", line 91, in __exit__
    raise dj_exc_value.with_traceback(traceback) from exc_value
  File "/Users/arnavshah/Documents/mafiawebsite/.venv/lib/python3.12/site-packages/django/db/backends/utils.py", line 105, in _execute
    return self.cursor.execute(sql, params)
           ^^^^^^^^^^^^^^^^^^^^^^^^^^^^^^^^
django.db.utils.ProgrammingError: relation "myapp_emailverification" does not exist
LINE 1: INSERT INTO "myapp_emailverification" ("user_id", "code", "c...
                    ^

"POST /register/ HTTP/1.1" 500 152314
You're accessing the development server over HTTPS, but it only supports HTTP.
You're accessing the development server over HTTPS, but it only supports HTTP.
You're accessing the development server over HTTPS, but it only supports HTTP.
You're accessing the development server over HTTPS, but it only supports HTTP.
You're accessing the development server over HTTPS, but it only supports HTTP.
You're accessing the development server over HTTPS, but it only supports HTTP.
You're accessing the development server over HTTPS, but it only supports HTTP.
You're accessing the development server over HTTPS, but it only supports HTTP.
You're accessing the development server over HTTPS, but it only supports HTTP.
You're accessing the development server over HTTPS, but it only supports HTTP.
You're accessing the development server over HTTPS, but it only supports HTTP.
You're accessing the development server over HTTPS, but it only supports HTTP.
You're accessing the development server over HTTPS, but it only supports HTTP.
You're accessing the development server over HTTPS, but it only supports HTTP.
You're accessing the development server over HTTPS, but it only supports HTTP.
You're accessing the development server over HTTPS, but it only supports HTTP.
You're accessing the development server over HTTPS, but it only supports HTTP.
You're accessing the development server over HTTPS, but it only supports HTTP.
Internal Server Error: /register/
Traceback (most recent call last):
  File "/Users/arnavshah/Documents/mafiawebsite/.venv/lib/python3.12/site-packages/django/core/handlers/exception.py", line 55, in inner
    response = get_response(request)
               ^^^^^^^^^^^^^^^^^^^^^
  File "/Users/arnavshah/Documents/mafiawebsite/.venv/lib/python3.12/site-packages/django/core/handlers/base.py", line 197, in _get_response
    response = wrapped_callback(request, *callback_args, **callback_kwargs)
               ^^^^^^^^^^^^^^^^^^^^^^^^^^^^^^^^^^^^^^^^^^^^^^^^^^^^^^^^^^^^
  File "/Users/arnavshah/Documents/mafiawebsite/myapp/views.py", line 418, in register
    send_mail(
  File "/Users/arnavshah/Documents/mafiawebsite/.venv/lib/python3.12/site-packages/django/core/mail/__init__.py", line 88, in send_mail
    return mail.send()
           ^^^^^^^^^^^
  File "/Users/arnavshah/Documents/mafiawebsite/.venv/lib/python3.12/site-packages/django/core/mail/message.py", line 301, in send
    return self.get_connection(fail_silently).send_messages([self])
           ^^^^^^^^^^^^^^^^^^^^^^^^^^^^^^^^^^^^^^^^^^^^^^^^^^^^^^^^
  File "/Users/arnavshah/Documents/mafiawebsite/.venv/lib/python3.12/site-packages/django/core/mail/backends/smtp.py", line 128, in send_messages
    new_conn_created = self.open()
                       ^^^^^^^^^^^
  File "/Users/arnavshah/Documents/mafiawebsite/.venv/lib/python3.12/site-packages/django/core/mail/backends/smtp.py", line 93, in open
    self.connection.starttls(context=self.ssl_context)
  File "/Library/Frameworks/Python.framework/Versions/3.12/lib/python3.12/smtplib.py", line 779, in starttls
    self.sock = context.wrap_socket(self.sock,
                ^^^^^^^^^^^^^^^^^^^^^^^^^^^^^^
  File "/Library/Frameworks/Python.framework/Versions/3.12/lib/python3.12/ssl.py", line 455, in wrap_socket
    return self.sslsocket_class._create(
           ^^^^^^^^^^^^^^^^^^^^^^^^^^^^^
  File "/Library/Frameworks/Python.framework/Versions/3.12/lib/python3.12/ssl.py", line 1042, in _create
    self.do_handshake()
  File "/Library/Frameworks/Python.framework/Versions/3.12/lib/python3.12/ssl.py", line 1320, in do_handshake
    self._sslobj.do_handshake()
ssl.SSLCertVerificationError: [SSL: CERTIFICATE_VERIFY_FAILED] certificate verify failed: unable to get local issuer certificate (_ssl.c:1000)
"POST /register/ HTTP/1.1" 500 111172
You're accessing the development server over HTTPS, but it only supports HTTP.
You're accessing the development server over HTTPS, but it only supports HTTP.
You're accessing the development server over HTTPS, but it only supports HTTP.
You're accessing the development server over HTTPS, but it only supports HTTP.
Internal Server Error: /register/
Traceback (most recent call last):
  File "/Users/arnavshah/Documents/mafiawebsite/.venv/lib/python3.12/site-packages/django/core/handlers/exception.py", line 55, in inner
    response = get_response(request)
               ^^^^^^^^^^^^^^^^^^^^^
  File "/Users/arnavshah/Documents/mafiawebsite/.venv/lib/python3.12/site-packages/django/core/handlers/base.py", line 197, in _get_response
    response = wrapped_callback(request, *callback_args, **callback_kwargs)
               ^^^^^^^^^^^^^^^^^^^^^^^^^^^^^^^^^^^^^^^^^^^^^^^^^^^^^^^^^^^^
  File "/Users/arnavshah/Documents/mafiawebsite/myapp/views.py", line 418, in register
    send_mail(
  File "/Users/arnavshah/Documents/mafiawebsite/.venv/lib/python3.12/site-packages/django/core/mail/__init__.py", line 88, in send_mail
    return mail.send()
           ^^^^^^^^^^^
  File "/Users/arnavshah/Documents/mafiawebsite/.venv/lib/python3.12/site-packages/django/core/mail/message.py", line 301, in send
    return self.get_connection(fail_silently).send_messages([self])
           ^^^^^^^^^^^^^^^^^^^^^^^^^^^^^^^^^^^^^^^^^^^^^^^^^^^^^^^^
  File "/Users/arnavshah/Documents/mafiawebsite/.venv/lib/python3.12/site-packages/django/core/mail/backends/smtp.py", line 128, in send_messages
    new_conn_created = self.open()
                       ^^^^^^^^^^^
  File "/Users/arnavshah/Documents/mafiawebsite/.venv/lib/python3.12/site-packages/django/core/mail/backends/smtp.py", line 93, in open
    self.connection.starttls(context=self.ssl_context)
                                     ^^^^^^^^^^^^^^^^
  File "/Users/arnavshah/Documents/mafiawebsite/.venv/lib/python3.12/site-packages/django/utils/functional.py", line 47, in __get__
    res = instance.__dict__[self.name] = self.func(instance)
                                         ^^^^^^^^^^^^^^^^^^^
  File "/Users/arnavshah/Documents/mafiawebsite/.venv/lib/python3.12/site-packages/django/core/mail/backends/smtp.py", line 63, in ssl_context
    ssl_context.load_cert_chain(self.ssl_certfile, self.ssl_keyfile)
ssl.SSLError: [SSL] PEM lib (_ssl.c:3916)
"POST /register/ HTTP/1.1" 500 99989
Not Found: /favicon.ico
"GET /favicon.ico HTTP/1.1" 404 9369
You're accessing the development server over HTTPS, but it only supports HTTP.
You're accessing the development server over HTTPS, but it only supports HTTP.
You're accessing the development server over HTTPS, but it only supports HTTP.
You're accessing the development server over HTTPS, but it only supports HTTP.
Internal Server Error: /register/
Traceback (most recent call last):
  File "/Users/arnavshah/Documents/mafiawebsite/.venv/lib/python3.12/site-packages/django/core/handlers/exception.py", line 55, in inner
    response = get_response(request)
               ^^^^^^^^^^^^^^^^^^^^^
  File "/Users/arnavshah/Documents/mafiawebsite/.venv/lib/python3.12/site-packages/django/core/handlers/base.py", line 197, in _get_response
    response = wrapped_callback(request, *callback_args, **callback_kwargs)
               ^^^^^^^^^^^^^^^^^^^^^^^^^^^^^^^^^^^^^^^^^^^^^^^^^^^^^^^^^^^^
  File "/Users/arnavshah/Documents/mafiawebsite/myapp/views.py", line 418, in register
    send_mail(
  File "/Users/arnavshah/Documents/mafiawebsite/.venv/lib/python3.12/site-packages/django/core/mail/__init__.py", line 88, in send_mail
    return mail.send()
           ^^^^^^^^^^^
  File "/Users/arnavshah/Documents/mafiawebsite/.venv/lib/python3.12/site-packages/django/core/mail/message.py", line 301, in send
    return self.get_connection(fail_silently).send_messages([self])
           ^^^^^^^^^^^^^^^^^^^^^^^^^^^^^^^^^^^^^^^^^^^^^^^^^^^^^^^^
  File "/Users/arnavshah/Documents/mafiawebsite/.venv/lib/python3.12/site-packages/django/core/mail/backends/smtp.py", line 128, in send_messages
    new_conn_created = self.open()
                       ^^^^^^^^^^^
  File "/Users/arnavshah/Documents/mafiawebsite/.venv/lib/python3.12/site-packages/django/core/mail/backends/smtp.py", line 93, in open
    self.connection.starttls(context=self.ssl_context)
                                     ^^^^^^^^^^^^^^^^
  File "/Users/arnavshah/Documents/mafiawebsite/.venv/lib/python3.12/site-packages/django/utils/functional.py", line 47, in __get__
    res = instance.__dict__[self.name] = self.func(instance)
                                         ^^^^^^^^^^^^^^^^^^^
  File "/Users/arnavshah/Documents/mafiawebsite/.venv/lib/python3.12/site-packages/django/core/mail/backends/smtp.py", line 63, in ssl_context
    ssl_context.load_cert_chain(self.ssl_certfile, self.ssl_keyfile)
ssl.SSLError: [SSL] PEM lib (_ssl.c:3916)
"POST /register/ HTTP/1.1" 500 99989
You're accessing the development server over HTTPS, but it only supports HTTP.
You're accessing the development server over HTTPS, but it only supports HTTP.
Internal Server Error: /register/
Traceback (most recent call last):
  File "/Users/arnavshah/Documents/mafiawebsite/.venv/lib/python3.12/site-packages/django/core/handlers/exception.py", line 55, in inner
    response = get_response(request)
               ^^^^^^^^^^^^^^^^^^^^^
  File "/Users/arnavshah/Documents/mafiawebsite/.venv/lib/python3.12/site-packages/django/core/handlers/base.py", line 197, in _get_response
    response = wrapped_callback(request, *callback_args, **callback_kwargs)
               ^^^^^^^^^^^^^^^^^^^^^^^^^^^^^^^^^^^^^^^^^^^^^^^^^^^^^^^^^^^^
  File "/Users/arnavshah/Documents/mafiawebsite/myapp/views.py", line 418, in register
    send_mail(
  File "/Users/arnavshah/Documents/mafiawebsite/.venv/lib/python3.12/site-packages/django/core/mail/__init__.py", line 88, in send_mail
    return mail.send()
           ^^^^^^^^^^^
  File "/Users/arnavshah/Documents/mafiawebsite/.venv/lib/python3.12/site-packages/django/core/mail/message.py", line 301, in send
    return self.get_connection(fail_silently).send_messages([self])
           ^^^^^^^^^^^^^^^^^^^^^^^^^^^^^^^^^^^^^^^^^^^^^^^^^^^^^^^^
  File "/Users/arnavshah/Documents/mafiawebsite/.venv/lib/python3.12/site-packages/django/core/mail/backends/smtp.py", line 128, in send_messages
    new_conn_created = self.open()
                       ^^^^^^^^^^^
  File "/Users/arnavshah/Documents/mafiawebsite/.venv/lib/python3.12/site-packages/django/core/mail/backends/smtp.py", line 93, in open
    self.connection.starttls(context=self.ssl_context)
  File "/Library/Frameworks/Python.framework/Versions/3.12/lib/python3.12/smtplib.py", line 779, in starttls
    self.sock = context.wrap_socket(self.sock,
                ^^^^^^^^^^^^^^^^^^^^^^^^^^^^^^
  File "/Library/Frameworks/Python.framework/Versions/3.12/lib/python3.12/ssl.py", line 455, in wrap_socket
    return self.sslsocket_class._create(
           ^^^^^^^^^^^^^^^^^^^^^^^^^^^^^
  File "/Library/Frameworks/Python.framework/Versions/3.12/lib/python3.12/ssl.py", line 1042, in _create
    self.do_handshake()
  File "/Library/Frameworks/Python.framework/Versions/3.12/lib/python3.12/ssl.py", line 1320, in do_handshake
    self._sslobj.do_handshake()
ssl.SSLCertVerificationError: [SSL: CERTIFICATE_VERIFY_FAILED] certificate verify failed: unable to get local issuer certificate (_ssl.c:1000)
"POST /register/ HTTP/1.1" 500 111202
You're accessing the development server over HTTPS, but it only supports HTTP.
You're accessing the development server over HTTPS, but it only supports HTTP.
Internal Server Error: /register/
Traceback (most recent call last):
  File "/Users/arnavshah/Documents/mafiawebsite/.venv/lib/python3.12/site-packages/django/core/handlers/exception.py", line 55, in inner
    response = get_response(request)
               ^^^^^^^^^^^^^^^^^^^^^
  File "/Users/arnavshah/Documents/mafiawebsite/.venv/lib/python3.12/site-packages/django/core/handlers/base.py", line 197, in _get_response
    response = wrapped_callback(request, *callback_args, **callback_kwargs)
               ^^^^^^^^^^^^^^^^^^^^^^^^^^^^^^^^^^^^^^^^^^^^^^^^^^^^^^^^^^^^
  File "/Users/arnavshah/Documents/mafiawebsite/myapp/views.py", line 418, in register
    send_mail(
  File "/Users/arnavshah/Documents/mafiawebsite/.venv/lib/python3.12/site-packages/django/core/mail/__init__.py", line 88, in send_mail
    return mail.send()
           ^^^^^^^^^^^
  File "/Users/arnavshah/Documents/mafiawebsite/.venv/lib/python3.12/site-packages/django/core/mail/message.py", line 301, in send
    return self.get_connection(fail_silently).send_messages([self])
           ^^^^^^^^^^^^^^^^^^^^^^^^^^^^^^^^^^^^^^^^^^^^^^^^^^^^^^^^
  File "/Users/arnavshah/Documents/mafiawebsite/.venv/lib/python3.12/site-packages/django/core/mail/backends/smtp.py", line 128, in send_messages
    new_conn_created = self.open()
                       ^^^^^^^^^^^
  File "/Users/arnavshah/Documents/mafiawebsite/.venv/lib/python3.12/site-packages/django/core/mail/backends/smtp.py", line 93, in open
    self.connection.starttls(context=self.ssl_context)
  File "/Library/Frameworks/Python.framework/Versions/3.12/lib/python3.12/smtplib.py", line 779, in starttls
    self.sock = context.wrap_socket(self.sock,
                ^^^^^^^^^^^^^^^^^^^^^^^^^^^^^^
  File "/Library/Frameworks/Python.framework/Versions/3.12/lib/python3.12/ssl.py", line 455, in wrap_socket
    return self.sslsocket_class._create(
           ^^^^^^^^^^^^^^^^^^^^^^^^^^^^^
  File "/Library/Frameworks/Python.framework/Versions/3.12/lib/python3.12/ssl.py", line 1042, in _create
    self.do_handshake()
  File "/Library/Frameworks/Python.framework/Versions/3.12/lib/python3.12/ssl.py", line 1320, in do_handshake
    self._sslobj.do_handshake()
ssl.SSLCertVerificationError: [SSL: CERTIFICATE_VERIFY_FAILED] certificate verify failed: unable to get local issuer certificate (_ssl.c:1000)
"POST /register/ HTTP/1.1" 500 111202
You're accessing the development server over HTTPS, but it only supports HTTP.
You're accessing the development server over HTTPS, but it only supports HTTP.
You're accessing the development server over HTTPS, but it only supports HTTP.
You're accessing the development server over HTTPS, but it only supports HTTP.
You're accessing the development server over HTTPS, but it only supports HTTP.
You're accessing the development server over HTTPS, but it only supports HTTP.
You're accessing the development server over HTTPS, but it only supports HTTP.
You're accessing the development server over HTTPS, but it only supports HTTP.
You're accessing the development server over HTTPS, but it only supports HTTP.
You're accessing the development server over HTTPS, but it only supports HTTP.
You're accessing the development server over HTTPS, but it only supports HTTP.
You're accessing the development server over HTTPS, but it only supports HTTP.
You're accessing the development server over HTTPS, but it only supports HTTP.
You're accessing the development server over HTTPS, but it only supports HTTP.
You're accessing the development server over HTTPS, but it only supports HTTP.
You're accessing the development server over HTTPS, but it only supports HTTP.
You're accessing the development server over HTTPS, but it only supports HTTP.
You're accessing the development server over HTTPS, but it only supports HTTP.
You're accessing the development server over HTTPS, but it only supports HTTP.
You're accessing the development server over HTTPS, but it only supports HTTP.
You're accessing the development server over HTTPS, but it only supports HTTP.
You're accessing the development server over HTTPS, but it only supports HTTP.
You're accessing the development server over HTTPS, but it only supports HTTP.
You're accessing the development server over HTTPS, but it only supports HTTP.
You're accessing the development server over HTTPS, but it only supports HTTP.
You're accessing the development server over HTTPS, but it only supports HTTP.
Internal Server Error: /register/
Traceback (most recent call last):
  File "/Users/arnavshah/Documents/mafiawebsite/.venv/lib/python3.12/site-packages/django/core/handlers/exception.py", line 55, in inner
    response = get_response(request)
               ^^^^^^^^^^^^^^^^^^^^^
  File "/Users/arnavshah/Documents/mafiawebsite/.venv/lib/python3.12/site-packages/django/core/handlers/base.py", line 197, in _get_response
    response = wrapped_callback(request, *callback_args, **callback_kwargs)
               ^^^^^^^^^^^^^^^^^^^^^^^^^^^^^^^^^^^^^^^^^^^^^^^^^^^^^^^^^^^^
  File "/Users/arnavshah/Documents/mafiawebsite/myapp/views.py", line 418, in register
    send_mail(
  File "/Users/arnavshah/Documents/mafiawebsite/.venv/lib/python3.12/site-packages/django/core/mail/__init__.py", line 88, in send_mail
    return mail.send()
           ^^^^^^^^^^^
  File "/Users/arnavshah/Documents/mafiawebsite/.venv/lib/python3.12/site-packages/django/core/mail/message.py", line 301, in send
    return self.get_connection(fail_silently).send_messages([self])
           ^^^^^^^^^^^^^^^^^^^^^^^^^^^^^^^^^^^^^^^^^^^^^^^^^^^^^^^^
  File "/Users/arnavshah/Documents/mafiawebsite/.venv/lib/python3.12/site-packages/django/core/mail/backends/smtp.py", line 128, in send_messages
    new_conn_created = self.open()
                       ^^^^^^^^^^^
  File "/Users/arnavshah/Documents/mafiawebsite/.venv/lib/python3.12/site-packages/django/core/mail/backends/smtp.py", line 95, in open
    self.connection.login(self.username, self.password)
  File "/Library/Frameworks/Python.framework/Versions/3.12/lib/python3.12/smtplib.py", line 716, in login
    raise SMTPNotSupportedError(
smtplib.SMTPNotSupportedError: SMTP AUTH extension not supported by server.
"POST /register/ HTTP/1.1" 500 10024
You're accessing the development server over HTTPS, but it only supports HTTP.
You're accessing the development server over HTTPS, but it only supports HTTP.
You're accessing the development server over HTTPS, but it only supports HTTP.
You're accessing the development server over HTTPS, but it only supports HTTP.
